Exceptions in C++ provide a way to handle errors or unexpected conditions in a program gracefully, allowing you to separate error-handling code from regular program flow. Below, I’ll explain the key concepts, mechanisms, and best practices for using exceptions in C++, with examples to illustrate each point.

---

### **1. What Are Exceptions?**
Exceptions are a mechanism to signal and handle errors or exceptional conditions that occur during program execution. Instead of using return codes or flags to indicate errors, C++ allows you to "throw" an exception when an error occurs, which can then be "caught" and handled elsewhere in the program.

- **Purpose**: To manage errors in a structured way, avoiding crashes and enabling recovery or graceful termination.
- **Key Components**:
  - **Throw**: Signals an error by throwing an exception object.
  - **Try**: Defines a block of code where exceptions might be thrown.
  - **Catch**: Handles the thrown exception.

---

### **2. Basic Syntax**
Here’s the basic structure of exception handling in C++:

```cpp
try {
    // Code that might throw an exception
    if (/* error condition */) {
        throw exception_object; // Throw an exception
    }
}
catch (exception_type variable) {
    // Handle the exception
}
```

- **try**: Encloses code that may throw an exception.
- **throw**: Used to throw an exception (e.g., an object, primitive type, or custom type).
- **catch**: Catches and handles the exception. You can have multiple `catch` blocks to handle different types of exceptions.

---

### **3. How Exceptions Work**
When an exception is thrown:
1. The program stops normal execution at the `throw` statement.
2. The runtime searches for the nearest `try` block enclosing the `throw`.
3. It then matches the thrown exception against the `catch` blocks associated with that `try`.
4. If a matching `catch` is found, the code inside it executes.
5. If no `catch` is found, the program may terminate (via `std::terminate`).

---

### **4. Example: Basic Exception Handling**
Here’s a simple example to demonstrate throwing and catching an exception:

```cpp
#include <iostream>
#include <string>

int divide(int a, int b) {
    if (b == 0) {
        throw std::string("Division by zero!");
    }
    return a / b;
}

int main() {
    try {
        int result = divide(10, 0);
        std::cout << "Result: " << result << std::endl;
    }
    catch (const std::string& error) {
        std::cout << "Error: " << error << std::endl;
    }
    return 0;
}
```

**Output**:
```
Error: Division by zero!
```

- **Explanation**:
  - The `divide` function checks for division by zero and throws a `std::string` exception if `b == 0`.
  - The `try` block in `main` calls `divide`.
  - The `catch` block catches the `std::string` exception and prints the error message.

---

### **5. Types of Exceptions**
In C++, you can throw any type as an exception (e.g., `int`, `std::string`, custom objects). However, it’s common to use:
- **Standard Exceptions**: Defined in `<stdexcept>` (e.g., `std::runtime_error`, `std::out_of_range`).
- **Custom Exceptions**: User-defined classes derived from `std::exception`.

#### **Standard Exceptions**
The `<stdexcept>` header provides several exception classes:
- `std::exception`: Base class for standard exceptions, with a virtual `what()` method.
- `std::runtime_error`: For runtime errors (e.g., `std::overflow_error`).
- `std::logic_error`: For logical errors in code (e.g., `std::out_of_range`).

Example using `std::runtime_error`:
```cpp
#include <iostream>
#include <stdexcept>

int main() {
    try {
        throw std::runtime_error("Something went wrong!");
    }
    catch (const std::exception& e) {
        std::cout << "Exception: " << e.what() << std::endl;
    }
    return 0;
}
```

**Output**:
```
Exception: Something went wrong!
```

#### **Custom Exceptions**
You can create custom exception classes by inheriting from `std::exception`:

```cpp
#include <iostream>
#include <stdexcept>

class MyException : public std::exception {
public:
    const char* what() const noexcept override {
        return "Custom exception occurred!";
    }
};

int main() {
    try {
        throw MyException();
    }
    catch (const std::exception& e) {
        std::cout << "Exception: " << e.what() << std::endl;
    }
    return 0;
}
```

**Output**:
```
Exception: Custom exception occurred!
```

- **Note**: The `noexcept` specifier ensures that `what()` doesn’t throw exceptions, which is a good practice.

---

### **6. Catching Multiple Exceptions**
You can use multiple `catch` blocks to handle different exception types. The order matters—more specific types should be caught before more general ones.

```cpp
#include <iostream>
#include <stdexcept>

int main() {
    try {
        throw std::out_of_range("Index out of bounds!");
    }
    catch (const std::out_of_range& e) {
        std::cout << "Out of range: " << e.what() << std::endl;
    }
    catch (const std::exception& e) {
        std::cout << "General exception: " << e.what() << std::endl;
    }
    catch (...) {
        std::cout << "Unknown exception!" << std::endl;
    }
    return 0;
}
```

**Output**:
```
Out of range: Index out of bounds!
```

- **catch (...)**: A catch-all block that handles any exception not caught by earlier blocks. Use it sparingly, as it can hide unexpected errors.

---

### **7. Exception Safety**
Exception safety refers to how well a program handles exceptions without causing resource leaks or inconsistent states. There are three levels of exception safety:
1. **Basic Guarantee**: No resource leaks, but the object’s state may be invalid.
2. **Strong Guarantee**: If an exception occurs, the program state remains unchanged (rollback semantics).
3. **No-throw Guarantee**: The operation never throws exceptions.

To achieve strong exception safety:
- Use RAII (Resource Acquisition Is Initialization) to manage resources (e.g., `std::unique_ptr`, `std::vector`).
- Avoid partial state changes in functions.

Example of RAII:
```cpp
#include <memory>
#include <iostream>

void process() {
    std::unique_ptr<int> ptr = std::make_unique<int>(42); // Automatically cleaned up
    throw std::runtime_error("Error occurred!");
}

int main() {
    try {
        process();
    }
    catch (const std::exception& e) {
        std::cout << e.what() << std::endl;
    }
    return 0;
}
```

- **Explanation**: Even if an exception is thrown, `std::unique_ptr` ensures the memory is freed.

---

### **8. The `noexcept` Specifier**
The `noexcept` keyword indicates that a function does not throw exceptions, helping the compiler optimize code and improve safety.

```cpp
void safeFunction() noexcept {
    // No exceptions thrown
}

void riskyFunction() {
    throw std::runtime_error("Error!");
}
```

- If a `noexcept` function throws an exception, `std::terminate` is called.
- Use `noexcept` for functions that are guaranteed not to throw (e.g., destructors, swap functions).

---

### **9. Stack Unwinding**
When an exception is thrown, the runtime performs **stack unwinding**:
- It destroys all automatic objects in scope (in reverse order of construction) before transferring control to the `catch` block.
- This ensures resources like stack-allocated objects are properly cleaned up.

Example:
```cpp
#include <iostream>

struct Resource {
    ~Resource() { std::cout << "Resource cleaned up!" << std::endl; }
};

void func() {
    Resource r;
    throw std::runtime_error("Error!");
}

int main() {
    try {
        func();
    }
    catch (const std::exception& e) {
        std::cout << e.what() << std::endl;
    }
}
```

**Output**:
```
Resource cleaned up!
Error!
```

---

### **10. Best Practices**
1. **Throw by Value, Catch by Reference**: Throw objects by value and catch them by `const` reference to avoid slicing and unnecessary copies.
   ```cpp
   throw std::runtime_error("Error"); // Throw by value
   catch (const std::runtime_error& e) { /* Handle */ } // Catch by reference
   ```
2. **Use Standard Exceptions**: Prefer `std::exception`-derived classes for clarity and compatibility.
3. **Avoid Throwing in Destructors**: Throwing in a destructor during stack unwinding calls `std::terminate`.
4. **Minimize Exception Use**: Use exceptions for exceptional conditions, not regular control flow.
5. **Ensure Exception Safety**: Use RAII and smart pointers to manage resources.
6. **Document Exceptions**: If a function throws, document the possible exception types (e.g., using comments or `noexcept(false)`).

---

### **11. Common Pitfalls**
- **Catching Everything**: Overusing `catch (...)` can hide bugs.
- **Throwing Raw Types**: Throwing `int` or `char*` makes it hard to convey error details.
- **Ignoring Exceptions**: Not handling exceptions can lead to program termination.
- **Resource Leaks**: Failing to use RAII can cause leaks when exceptions occur.

---

### **12. Exceptions in Modern C++**
- **C++11 and Later**: Introduced `noexcept`, `std::exception_ptr` for passing exceptions between threads, and `std::nested_exception` for chaining exceptions.
- **C++17**: Added `std::uncaught_exceptions()` to check for active exceptions.
- **Performance**: Exceptions have overhead (stack unwinding, object creation), so use them judiciously in performance-critical code.

---

### **13. Advanced Example: Custom Exception with Context**
```cpp
#include <iostream>
#include <stdexcept>
#include <string>

class DatabaseError : public std::runtime_error {
public:
    DatabaseError(const std::string& msg, int errorCode)
        : std::runtime_error(msg), code(errorCode) {}
    int getErrorCode() const { return code; }
private:
    int code;
};

void accessDatabase(int id) {
    if (id < 0) {
        throw DatabaseError("Invalid ID", 1001);
    }
    std::cout << "Accessing database with ID: " << id << std::endl;
}

int main() {
    try {
        accessDatabase(-1);
    }
    catch (const DatabaseError& e) {
        std::cout << "Database error: " << e.what() << ", Code: " << e.getErrorCode() << std::endl;
    }
    catch (const std::exception& e) {
        std::cout << "Standard exception: " << e.what() << std::endl;
    }
    catch (...) {
        std::cout << "Unknown error!" << std::endl;
    }
    return 0;
}
```

**Output**:
```
Database error: Invalid ID, Code: 1001
```

- **Explanation**: This shows a custom exception with additional context (error code), proper inheritance, and layered exception handling.

---

### **14. When to Use Exceptions**
- **Use Exceptions For**:
  - Unexpected errors (e.g., file not found, network failure).
  - Conditions that prevent normal program continuation.
- **Avoid Exceptions For**:
  - Expected conditions (e.g., user input validation).
  - Control flow (e.g., instead of loops or conditionals).

---

### **15. Conclusion**
Exceptions in C++ provide a robust mechanism for error handling, allowing you to manage errors cleanly and maintain program stability. By using standard exceptions, RAII, and best practices like `noexcept`, you can write safer and more maintainable code. Always consider exception safety and avoid overusing exceptions for non-error scenarios.

If you have specific questions or need more examples (e.g., exceptions in templates, multithreading, or performance considerations), let me know!


__________________________________-
In C++, the ability of a program to stop execution in a `try` block and jump directly to a `catch` block when an exception is thrown is a fundamental difference from C, which lacks built-in exception handling. Let me explain how this works, why it happens, and how it contrasts with C-style error handling, keeping it concise and tailored to your background in C.

---

### **Why and How It Happens**
In C++, exceptions provide a structured way to handle errors by transferring control from the point of error to an appropriate handler. Here’s the mechanism:

1. **Throwing an Exception**:
   - Inside a `try` block, if a `throw` statement is executed (e.g., `throw std::runtime_error("Error!")`), the program immediately stops executing the current function’s code.
   - The `throw` creates an exception object and signals that an error has occurred.

2. **Stack Unwinding**:
   - The C++ runtime begins **stack unwinding**: it exits the current function and all calling functions until it finds a `try` block with a matching `catch` block.
   - During unwinding, all automatic (stack-allocated) objects in the affected scopes are destroyed in reverse order of construction, ensuring no resource leaks (this is where RAII—Resource Acquisition Is Initialization—shines).

3. **Transfer to Catch Block**:
   - Once a matching `catch` block is found (based on the type of the thrown exception), control jumps directly to that block, skipping any remaining code in the `try` block or subsequent functions in the call stack.
   - If no `catch` block is found, the program terminates (via `std::terminate`).

This is different from C, where error handling typically relies on:
- Return codes (e.g., returning `-1` or `NULL` to indicate failure).
- Manual checks (e.g., `if (result == NULL) { /* handle error */ }`).
- No automatic mechanism to jump out of a function or clean up resources.

---

### **Example to Illustrate**
Here’s a simple C++ example to show how control jumps from `try` to `catch`:

```cpp
#include <iostream>
#include <stdexcept>

void riskyFunction(int value) {
    if (value < 0) {
        throw std::runtime_error("Negative value not allowed!");
    }
    std::cout << "This won't print if exception is thrown" << std::endl;
}

int main() {
    try {
        std::cout << "Starting try block" << std::endl;
        riskyFunction(-1); // Throws an exception
        std::cout << "This line is skipped" << std::endl;
    }
    catch (const std::runtime_error& e) {
        std::cout << "Caught exception: " << e.what() << std::endl;
    }
    std::cout << "Program continues" << std::endl;
    return 0;
}
```

**Output**:
```
Starting try block
Caught exception: Negative value not allowed!
Program continues
```

- **What Happens**:
  - The `try` block starts, and `riskyFunction(-1)` is called.
  - Inside `riskyFunction`, the `throw` statement is executed when `value < 0`.
  - The program immediately stops executing `riskyFunction` (skipping the `std::cout` in that function).
  - Control jumps out of the `try` block in `main`, skipping the second `std::cout` in the `try` block.
  - The `catch` block handles the `std::runtime_error`, printing the error message.
  - Execution continues after the `catch` block.

---

### **Contrast with C**
In C, you’d handle errors manually, like this:

```c
#include <stdio.h>
#include <stdlib.h>

int riskyFunction(int value) {
    if (value < 0) {
        return -1; // Error code
    }
    printf("Processing value: %d\n", value);
    return 0; // Success
}

int main() {
    int result = riskyFunction(-1);
    if (result == -1) {
        printf("Error: Negative value not allowed!\n");
    } else {
        printf("Success\n");
    }
    printf("Program continues\n");
    return 0;
}
```

**Output**:
```
Error: Negative value not allowed!
Program continues
```

- **Key Differences**:
  - In C, you explicitly check the return value (`result == -1`) to handle errors, and execution continues normally unless you use constructs like `goto` or `return`.
  - In C++, a `throw` automatically interrupts the normal flow and jumps to the `catch` block, without requiring manual checks at every function call.
  - C++’s stack unwinding ensures automatic cleanup of stack objects (e.g., via destructors), whereas in C, you must manually free resources (e.g., `free()` for allocated memory) before returning.

---

### **Why This Mechanism Exists**
- **Separation of Concerns**: Exceptions separate error-handling code from normal logic, making code cleaner compared to C’s error-checking boilerplate.
- **Automatic Cleanup**: C++’s RAII ensures resources (memory, files, etc.) are cleaned up during stack unwinding, reducing the risk of leaks.
- **Propagation**: Exceptions can propagate up the call stack to the appropriate handler, unlike C’s return codes, which require manual propagation through every function.

---

### **How It’s Implemented Under the Hood**
- **Exception Object**: When you `throw` an object, it’s copied (or moved in C++11+) to a safe location managed by the runtime.
- **Stack Unwinding**: The runtime walks the call stack, destroying local objects and looking for a `try`/`catch` block that matches the exception type.
- **Performance**: Throwing exceptions has overhead (copying objects, unwinding), which is why they’re used for exceptional cases, not regular control flow.

---

### **For C Programmers: Things to Watch Out For**
1. **Unfamiliar Control Flow**: The jump from `throw` to `catch` can feel abrupt if you’re used to C’s linear flow. Think of it like a `longjmp` in C, but safer and with automatic cleanup.
2. **Resource Management**: In C, you manually manage resources. In C++, use RAII (e.g., `std::unique_ptr`, `std::string`) to avoid leaks when exceptions occur.
3. **Catch by Reference**: Always catch exceptions by `const` reference (e.g., `catch (const std::exception& e)`) to avoid slicing or unnecessary copies.
4. **Don’t Overuse Exceptions**: Unlike C’s return codes, exceptions are for errors that disrupt normal flow, not for expected conditions like invalid user input.

---

### **Practical Example with RAII**
To show how C++ handles cleanup (unlike C’s manual approach):

```cpp
#include <iostream>
#include <stdexcept>

struct Resource {
    ~Resource() { std::cout << "Resource cleaned up!" << std::endl; }
};

void riskyFunction() {
    Resource r; // RAII ensures cleanup
    throw std::runtime_error("Error!");
}

int main() {
    try {
        riskyFunction();
        std::cout << "This is skipped" << std::endl;
    }
    catch (const std::runtime_error& e) {
        std::cout << "Caught: " << e.what() << std::endl;
    }
    return 0;
}
```

**Output**:
```
Resource cleaned up!
Caught: Error!
```

- **Explanation**: When the exception is thrown, the `Resource` object’s destructor runs automatically during stack unwinding, ensuring cleanup. In C, you’d need to manually free resources before returning an error code.

---

### **Conclusion**
The jump from a `try` block to a `catch` block in C++ is enabled by the exception-handling mechanism, which automates error propagation and resource cleanup—features absent in C. This makes error handling more robust but requires understanding stack unwinding and RAII to avoid pitfalls. If you’re transitioning from C, focus on using standard exceptions (e.g., `std::runtime_error`) and RAII to manage resources safely.

If you have a specific scenario or code you’d like to explore with exceptions, let me know, and I can tailor an example!